<?xml version="1.0" encoding="UTF-8"?>
<testng-results ignored="1" total="6" passed="5" failed="0" skipped="0">
  <reporter-output>
  </reporter-output>
  <suite started-at="2022-05-05T14:07:57 EEST" name="Suite3" finished-at="2022-05-05T14:07:58 EEST" duration-ms="130">
    <groups>
      <group name="method1">
        <method signature="ExceptionTest.f2()[pri:0, instance:example_tests.ExceptionTest@4a668b6e]" name="f2" class="example_tests.ExceptionTest"/>
      </group> <!-- method1 -->
      <group name="method2">
        <method signature="ExceptionTest.f3()[pri:0, instance:example_tests.ExceptionTest@4a668b6e]" name="f3" class="example_tests.ExceptionTest"/>
      </group> <!-- method2 -->
      <group name="method3">
        <method signature="ExceptionTest.f4()[pri:0, instance:example_tests.ExceptionTest@4a668b6e]" name="f4" class="example_tests.ExceptionTest"/>
      </group> <!-- method3 -->
    </groups>
    <test started-at="2022-05-05T14:07:57 EEST" name="Test31" finished-at="2022-05-05T14:07:58 EEST" duration-ms="130">
      <class name="example_tests.ExceptionTest">
        <test-method signature="f()[pri:0, instance:example_tests.ExceptionTest@4a668b6e]" started-at="2022-05-05T14:07:57 EEST" name="f" finished-at="2022-05-05T14:07:58 EEST" duration-ms="14" status="PASS">
          <exception class="java.lang.ArithmeticException">
            <message>
              <![CDATA[/ by zero]]>
            </message>
            <full-stacktrace>
              <![CDATA[java.lang.ArithmeticException: / by zero
at example_tests.ExceptionTest.f(ExceptionTest.java:10)
at java.base/jdk.internal.reflect.NativeMethodAccessorImpl.invoke0(Native Method)
at java.base/jdk.internal.reflect.NativeMethodAccessorImpl.invoke(NativeMethodAccessorImpl.java:78)
at java.base/jdk.internal.reflect.DelegatingMethodAccessorImpl.invoke(DelegatingMethodAccessorImpl.java:43)
at java.base/java.lang.reflect.Method.invoke(Method.java:567)
at org.testng.internal.MethodInvocationHelper.invokeMethod(MethodInvocationHelper.java:133)
at org.testng.internal.TestInvoker.invokeMethod(TestInvoker.java:598)
at org.testng.internal.TestInvoker.invokeTestMethod(TestInvoker.java:173)
at org.testng.internal.MethodRunner.runInSequence(MethodRunner.java:46)
at org.testng.internal.TestInvoker$MethodInvocationAgent.invoke(TestInvoker.java:824)
at org.testng.internal.TestInvoker.invokeTestMethods(TestInvoker.java:146)
at org.testng.internal.TestMethodWorker.invokeTestMethods(TestMethodWorker.java:146)
at org.testng.internal.TestMethodWorker.run(TestMethodWorker.java:128)
at java.base/java.util.ArrayList.forEach(ArrayList.java:1511)
at org.testng.TestRunner.privateRun(TestRunner.java:794)
at org.testng.TestRunner.run(TestRunner.java:596)
at org.testng.SuiteRunner.runTest(SuiteRunner.java:377)
at org.testng.SuiteRunner.runSequentially(SuiteRunner.java:371)
at org.testng.SuiteRunner.privateRun(SuiteRunner.java:332)
at org.testng.SuiteRunner.run(SuiteRunner.java:276)
at org.testng.SuiteRunnerWorker.runSuite(SuiteRunnerWorker.java:53)
at org.testng.SuiteRunnerWorker.run(SuiteRunnerWorker.java:96)
at org.testng.TestNG.runSuitesSequentially(TestNG.java:1212)
at org.testng.TestNG.runSuitesLocally(TestNG.java:1134)
at org.testng.TestNG.runSuites(TestNG.java:1063)
at org.testng.TestNG.run(TestNG.java:1031)
at org.testng.remote.AbstractRemoteTestNG.run(AbstractRemoteTestNG.java:115)
at org.testng.remote.RemoteTestNG.initAndRun(RemoteTestNG.java:251)
at org.testng.remote.RemoteTestNG.main(RemoteTestNG.java:77)
]]>
            </full-stacktrace>
          </exception> <!-- java.lang.ArithmeticException -->
          <reporter-output>
          </reporter-output>
        </test-method> <!-- f -->
        <test-method signature="f2()[pri:0, instance:example_tests.ExceptionTest@4a668b6e]" started-at="2022-05-05T14:07:58 EEST" name="f2" finished-at="2022-05-05T14:07:58 EEST" duration-ms="2" status="PASS">
          <reporter-output>
          </reporter-output>
        </test-method> <!-- f2 -->
        <test-method signature="f3()[pri:0, instance:example_tests.ExceptionTest@4a668b6e]" started-at="2022-05-05T14:07:58 EEST" name="f3" finished-at="2022-05-05T14:07:58 EEST" duration-ms="2" status="PASS">
          <reporter-output>
          </reporter-output>
        </test-method> <!-- f3 -->
        <test-method signature="f4()[pri:0, instance:example_tests.ExceptionTest@4a668b6e]" started-at="2022-05-05T14:07:58 EEST" name="f4" finished-at="2022-05-05T14:07:58 EEST" duration-ms="7" status="PASS">
          <reporter-output>
          </reporter-output>
        </test-method> <!-- f4 -->
        <test-method signature="f5(int)[pri:0, instance:example_tests.ExceptionTest@4a668b6e]" started-at="2022-05-05T14:07:58 EEST" name="f5" finished-at="2022-05-05T14:07:58 EEST" duration-ms="4" status="PASS">
          <params>
            <param index="0">
              <value>
                <![CDATA[345]]>
              </value>
            </param>
          </params>
          <reporter-output>
          </reporter-output>
        </test-method> <!-- f5 -->
      </class> <!-- example_tests.ExceptionTest -->
    </test> <!-- Test31 -->
  </suite> <!-- Suite3 -->
</testng-results>
